[2025-05-12T19:24:51.344+0000] {taskinstance.py:1159} INFO - Dependencies all met for dep_context=non-requeueable deps ti=<TaskInstance: stock_etl_alpha_vantage_minio_only.extract_stock_data manual__2025-05-12T19:21:57.226545+00:00 [queued]>
[2025-05-12T19:24:51.368+0000] {taskinstance.py:1159} INFO - Dependencies all met for dep_context=requeueable deps ti=<TaskInstance: stock_etl_alpha_vantage_minio_only.extract_stock_data manual__2025-05-12T19:21:57.226545+00:00 [queued]>
[2025-05-12T19:24:51.368+0000] {taskinstance.py:1361} INFO - Starting attempt 1 of 1
[2025-05-12T19:24:51.395+0000] {taskinstance.py:1382} INFO - Executing <Task(PythonOperator): extract_stock_data> on 2025-05-12 19:21:57.226545+00:00
[2025-05-12T19:24:51.411+0000] {standard_task_runner.py:57} INFO - Started process 213 to run task
[2025-05-12T19:24:51.420+0000] {standard_task_runner.py:84} INFO - Running: ['***', 'tasks', 'run', 'stock_etl_alpha_vantage_minio_only', 'extract_stock_data', 'manual__2025-05-12T19:21:57.226545+00:00', '--job-id', '2', '--raw', '--subdir', 'DAGS_FOLDER/stocks_vantage.py', '--cfg-path', '/tmp/tmp5qkl6k1a']
[2025-05-12T19:24:51.426+0000] {standard_task_runner.py:85} INFO - Job 2: Subtask extract_stock_data
[2025-05-12T19:24:51.519+0000] {task_command.py:416} INFO - Running <TaskInstance: stock_etl_alpha_vantage_minio_only.extract_stock_data manual__2025-05-12T19:21:57.226545+00:00 [running]> on host dca9766e1a4c
[2025-05-12T19:24:51.654+0000] {taskinstance.py:1662} INFO - Exporting env vars: AIRFLOW_CTX_DAG_OWNER='***' AIRFLOW_CTX_DAG_ID='stock_etl_alpha_vantage_minio_only' AIRFLOW_CTX_TASK_ID='extract_stock_data' AIRFLOW_CTX_EXECUTION_DATE='2025-05-12T19:21:57.226545+00:00' AIRFLOW_CTX_TRY_NUMBER='1' AIRFLOW_CTX_DAG_RUN_ID='manual__2025-05-12T19:21:57.226545+00:00'
[2025-05-12T19:25:25.843+0000] {taskinstance.py:1937} ERROR - Task failed with exception
Traceback (most recent call last):
  File "/home/airflow/.local/lib/python3.10/site-packages/urllib3/connection.py", line 174, in _new_conn
    conn = connection.create_connection(
  File "/home/airflow/.local/lib/python3.10/site-packages/urllib3/util/connection.py", line 72, in create_connection
    for res in socket.getaddrinfo(host, port, family, socket.SOCK_STREAM):
  File "/usr/local/lib/python3.10/socket.py", line 955, in getaddrinfo
    for res in _socket.getaddrinfo(host, port, family, type, proto, flags):
socket.gaierror: [Errno -3] Temporary failure in name resolution

During handling of the above exception, another exception occurred:

Traceback (most recent call last):
  File "/home/airflow/.local/lib/python3.10/site-packages/urllib3/connectionpool.py", line 715, in urlopen
    httplib_response = self._make_request(
  File "/home/airflow/.local/lib/python3.10/site-packages/urllib3/connectionpool.py", line 404, in _make_request
    self._validate_conn(conn)
  File "/home/airflow/.local/lib/python3.10/site-packages/urllib3/connectionpool.py", line 1058, in _validate_conn
    conn.connect()
  File "/home/airflow/.local/lib/python3.10/site-packages/urllib3/connection.py", line 363, in connect
    self.sock = conn = self._new_conn()
  File "/home/airflow/.local/lib/python3.10/site-packages/urllib3/connection.py", line 186, in _new_conn
    raise NewConnectionError(
urllib3.exceptions.NewConnectionError: <urllib3.connection.HTTPSConnection object at 0x7bdc6f4a38e0>: Failed to establish a new connection: [Errno -3] Temporary failure in name resolution

During handling of the above exception, another exception occurred:

Traceback (most recent call last):
  File "/home/airflow/.local/lib/python3.10/site-packages/requests/adapters.py", line 486, in send
    resp = conn.urlopen(
  File "/home/airflow/.local/lib/python3.10/site-packages/urllib3/connectionpool.py", line 799, in urlopen
    retries = retries.increment(
  File "/home/airflow/.local/lib/python3.10/site-packages/urllib3/util/retry.py", line 592, in increment
    raise MaxRetryError(_pool, url, error or ResponseError(cause))
urllib3.exceptions.MaxRetryError: HTTPSConnectionPool(host='www.alphavantage.co', port=443): Max retries exceeded with url: /query?function=TIME_SERIES_DAILY&symbol=AAPL&outputsize=full&apikey=D4FOXZ3SY45T4YFI&datatype=json (Caused by NewConnectionError('<urllib3.connection.HTTPSConnection object at 0x7bdc6f4a38e0>: Failed to establish a new connection: [Errno -3] Temporary failure in name resolution'))

During handling of the above exception, another exception occurred:

Traceback (most recent call last):
  File "/home/airflow/.local/lib/python3.10/site-packages/airflow/operators/python.py", line 192, in execute
    return_value = self.execute_callable()
  File "/home/airflow/.local/lib/python3.10/site-packages/airflow/operators/python.py", line 209, in execute_callable
    return self.python_callable(*self.op_args, **self.op_kwargs)
  File "/opt/airflow/dags/stocks_vantage.py", line 34, in extract_stock_data
    data, meta_data = ts.get_daily(symbol=SYMBOL, outputsize='full')
  File "/home/airflow/.local/lib/python3.10/site-packages/alpha_vantage/alphavantage.py", line 218, in _format_wrapper
    call_response, data_key, meta_data_key = func(
  File "/home/airflow/.local/lib/python3.10/site-packages/alpha_vantage/alphavantage.py", line 160, in _call_wrapper
    return self._handle_api_call(url), data_key, meta_data_key
  File "/home/airflow/.local/lib/python3.10/site-packages/alpha_vantage/alphavantage.py", line 351, in _handle_api_call
    response = requests.get(url, proxies=self.proxy, headers=self.headers)
  File "/home/airflow/.local/lib/python3.10/site-packages/requests/api.py", line 73, in get
    return request("get", url, params=params, **kwargs)
  File "/home/airflow/.local/lib/python3.10/site-packages/requests/api.py", line 59, in request
    return session.request(method=method, url=url, **kwargs)
  File "/home/airflow/.local/lib/python3.10/site-packages/requests/sessions.py", line 589, in request
    resp = self.send(prep, **send_kwargs)
  File "/home/airflow/.local/lib/python3.10/site-packages/requests/sessions.py", line 703, in send
    r = adapter.send(request, **kwargs)
  File "/home/airflow/.local/lib/python3.10/site-packages/requests/adapters.py", line 519, in send
    raise ConnectionError(e, request=request)
requests.exceptions.ConnectionError: HTTPSConnectionPool(host='www.alphavantage.co', port=443): Max retries exceeded with url: /query?function=TIME_SERIES_DAILY&symbol=AAPL&outputsize=full&apikey=D4FOXZ3SY45T4YFI&datatype=json (Caused by NewConnectionError('<urllib3.connection.HTTPSConnection object at 0x7bdc6f4a38e0>: Failed to establish a new connection: [Errno -3] Temporary failure in name resolution'))
[2025-05-12T19:25:29.206+0000] {taskinstance.py:1400} INFO - Marking task as FAILED. dag_id=stock_etl_alpha_vantage_minio_only, task_id=extract_stock_data, execution_date=20250512T192157, start_date=20250512T192451, end_date=20250512T192529
[2025-05-12T19:25:34.434+0000] {standard_task_runner.py:104} ERROR - Failed to execute job 2 for task extract_stock_data (HTTPSConnectionPool(host='www.alphavantage.co', port=443): Max retries exceeded with url: /query?function=TIME_SERIES_DAILY&symbol=AAPL&outputsize=full&apikey=D4FOXZ3SY45T4YFI&datatype=json (Caused by NewConnectionError('<urllib3.connection.HTTPSConnection object at 0x7bdc6f4a38e0>: Failed to establish a new connection: [Errno -3] Temporary failure in name resolution')); 213)
[2025-05-12T19:25:34.735+0000] {local_task_job_runner.py:228} INFO - Task exited with return code 1
[2025-05-12T19:25:37.178+0000] {taskinstance.py:2778} INFO - 0 downstream tasks scheduled from follow-on schedule check
