[2025-05-12T00:00:01.046+0000] {taskinstance.py:1159} INFO - Dependencies all met for dep_context=non-requeueable deps ti=<TaskInstance: stock_etl_alpha_vantage_minio_only.extract_stock_data scheduled__2025-05-11T00:00:00+00:00 [queued]>
[2025-05-12T00:00:01.056+0000] {taskinstance.py:1159} INFO - Dependencies all met for dep_context=requeueable deps ti=<TaskInstance: stock_etl_alpha_vantage_minio_only.extract_stock_data scheduled__2025-05-11T00:00:00+00:00 [queued]>
[2025-05-12T00:00:01.057+0000] {taskinstance.py:1361} INFO - Starting attempt 1 of 1
[2025-05-12T00:00:01.076+0000] {taskinstance.py:1382} INFO - Executing <Task(PythonOperator): extract_stock_data> on 2025-05-11 00:00:00+00:00
[2025-05-12T00:00:01.086+0000] {standard_task_runner.py:57} INFO - Started process 4570 to run task
[2025-05-12T00:00:01.093+0000] {standard_task_runner.py:84} INFO - Running: ['***', 'tasks', 'run', 'stock_etl_alpha_vantage_minio_only', 'extract_stock_data', 'scheduled__2025-05-11T00:00:00+00:00', '--job-id', '16', '--raw', '--subdir', 'DAGS_FOLDER/stocks_vantage.py', '--cfg-path', '/tmp/tmp4i78laq1']
[2025-05-12T00:00:01.097+0000] {standard_task_runner.py:85} INFO - Job 16: Subtask extract_stock_data
[2025-05-12T00:00:01.186+0000] {task_command.py:416} INFO - Running <TaskInstance: stock_etl_alpha_vantage_minio_only.extract_stock_data scheduled__2025-05-11T00:00:00+00:00 [running]> on host 5e9778614adc
[2025-05-12T00:00:01.307+0000] {taskinstance.py:1662} INFO - Exporting env vars: AIRFLOW_CTX_DAG_OWNER='***' AIRFLOW_CTX_DAG_ID='stock_etl_alpha_vantage_minio_only' AIRFLOW_CTX_TASK_ID='extract_stock_data' AIRFLOW_CTX_EXECUTION_DATE='2025-05-11T00:00:00+00:00' AIRFLOW_CTX_TRY_NUMBER='1' AIRFLOW_CTX_DAG_RUN_ID='scheduled__2025-05-11T00:00:00+00:00'
[2025-05-12T00:00:08.772+0000] {python.py:194} INFO - Done. Returned value was: None
[2025-05-12T00:00:08.789+0000] {taskinstance.py:1400} INFO - Marking task as SUCCESS. dag_id=stock_etl_alpha_vantage_minio_only, task_id=extract_stock_data, execution_date=20250511T000000, start_date=20250512T000001, end_date=20250512T000008
[2025-05-12T00:00:08.864+0000] {local_task_job_runner.py:228} INFO - Task exited with return code 0
[2025-05-12T00:00:08.915+0000] {taskinstance.py:2778} INFO - 0 downstream tasks scheduled from follow-on schedule check
[2025-05-12T08:57:41.378+0000] {taskinstance.py:1159} INFO - Dependencies all met for dep_context=non-requeueable deps ti=<TaskInstance: stock_etl_alpha_vantage_minio_only.extract_stock_data scheduled__2025-05-11T00:00:00+00:00 [queued]>
[2025-05-12T08:57:41.427+0000] {taskinstance.py:1159} INFO - Dependencies all met for dep_context=requeueable deps ti=<TaskInstance: stock_etl_alpha_vantage_minio_only.extract_stock_data scheduled__2025-05-11T00:00:00+00:00 [queued]>
[2025-05-12T08:57:41.436+0000] {taskinstance.py:1361} INFO - Starting attempt 1 of 1
[2025-05-12T08:57:41.627+0000] {taskinstance.py:1382} INFO - Executing <Task(PythonOperator): extract_stock_data> on 2025-05-11 00:00:00+00:00
[2025-05-12T08:57:41.679+0000] {standard_task_runner.py:57} INFO - Started process 261 to run task
[2025-05-12T08:57:41.722+0000] {standard_task_runner.py:84} INFO - Running: ['***', 'tasks', 'run', 'stock_etl_alpha_vantage_minio_only', 'extract_stock_data', 'scheduled__2025-05-11T00:00:00+00:00', '--job-id', '4', '--raw', '--subdir', 'DAGS_FOLDER/stocks_vantage.py', '--cfg-path', '/tmp/tmpox2e94xr']
[2025-05-12T08:57:41.741+0000] {standard_task_runner.py:85} INFO - Job 4: Subtask extract_stock_data
[2025-05-12T08:57:43.084+0000] {task_command.py:416} INFO - Running <TaskInstance: stock_etl_alpha_vantage_minio_only.extract_stock_data scheduled__2025-05-11T00:00:00+00:00 [running]> on host c2f99ff1d820
[2025-05-12T08:57:45.767+0000] {taskinstance.py:1662} INFO - Exporting env vars: AIRFLOW_CTX_DAG_OWNER='***' AIRFLOW_CTX_DAG_ID='stock_etl_alpha_vantage_minio_only' AIRFLOW_CTX_TASK_ID='extract_stock_data' AIRFLOW_CTX_EXECUTION_DATE='2025-05-11T00:00:00+00:00' AIRFLOW_CTX_TRY_NUMBER='1' AIRFLOW_CTX_DAG_RUN_ID='scheduled__2025-05-11T00:00:00+00:00'
[2025-05-12T08:58:04.202+0000] {taskinstance.py:1937} ERROR - Task failed with exception
Traceback (most recent call last):
  File "/home/airflow/.local/lib/python3.10/site-packages/urllib3/connection.py", line 174, in _new_conn
    conn = connection.create_connection(
  File "/home/airflow/.local/lib/python3.10/site-packages/urllib3/util/connection.py", line 72, in create_connection
    for res in socket.getaddrinfo(host, port, family, socket.SOCK_STREAM):
  File "/usr/local/lib/python3.10/socket.py", line 955, in getaddrinfo
    for res in _socket.getaddrinfo(host, port, family, type, proto, flags):
socket.gaierror: [Errno -3] Temporary failure in name resolution

During handling of the above exception, another exception occurred:

Traceback (most recent call last):
  File "/home/airflow/.local/lib/python3.10/site-packages/urllib3/connectionpool.py", line 715, in urlopen
    httplib_response = self._make_request(
  File "/home/airflow/.local/lib/python3.10/site-packages/urllib3/connectionpool.py", line 404, in _make_request
    self._validate_conn(conn)
  File "/home/airflow/.local/lib/python3.10/site-packages/urllib3/connectionpool.py", line 1058, in _validate_conn
    conn.connect()
  File "/home/airflow/.local/lib/python3.10/site-packages/urllib3/connection.py", line 363, in connect
    self.sock = conn = self._new_conn()
  File "/home/airflow/.local/lib/python3.10/site-packages/urllib3/connection.py", line 186, in _new_conn
    raise NewConnectionError(
urllib3.exceptions.NewConnectionError: <urllib3.connection.HTTPSConnection object at 0x7fd0a6624130>: Failed to establish a new connection: [Errno -3] Temporary failure in name resolution

During handling of the above exception, another exception occurred:

Traceback (most recent call last):
  File "/home/airflow/.local/lib/python3.10/site-packages/requests/adapters.py", line 486, in send
    resp = conn.urlopen(
  File "/home/airflow/.local/lib/python3.10/site-packages/urllib3/connectionpool.py", line 799, in urlopen
    retries = retries.increment(
  File "/home/airflow/.local/lib/python3.10/site-packages/urllib3/util/retry.py", line 592, in increment
    raise MaxRetryError(_pool, url, error or ResponseError(cause))
urllib3.exceptions.MaxRetryError: HTTPSConnectionPool(host='www.alphavantage.co', port=443): Max retries exceeded with url: /query?function=TIME_SERIES_DAILY&symbol=AAPL&outputsize=full&apikey=D4FOXZ3SY45T4YFI&datatype=json (Caused by NewConnectionError('<urllib3.connection.HTTPSConnection object at 0x7fd0a6624130>: Failed to establish a new connection: [Errno -3] Temporary failure in name resolution'))

During handling of the above exception, another exception occurred:

Traceback (most recent call last):
  File "/home/airflow/.local/lib/python3.10/site-packages/airflow/operators/python.py", line 192, in execute
    return_value = self.execute_callable()
  File "/home/airflow/.local/lib/python3.10/site-packages/airflow/operators/python.py", line 209, in execute_callable
    return self.python_callable(*self.op_args, **self.op_kwargs)
  File "/opt/airflow/dags/stocks_vantage.py", line 34, in extract_stock_data
    data, meta_data = ts.get_daily(symbol=SYMBOL, outputsize='full')
  File "/home/airflow/.local/lib/python3.10/site-packages/alpha_vantage/alphavantage.py", line 218, in _format_wrapper
    call_response, data_key, meta_data_key = func(
  File "/home/airflow/.local/lib/python3.10/site-packages/alpha_vantage/alphavantage.py", line 160, in _call_wrapper
    return self._handle_api_call(url), data_key, meta_data_key
  File "/home/airflow/.local/lib/python3.10/site-packages/alpha_vantage/alphavantage.py", line 351, in _handle_api_call
    response = requests.get(url, proxies=self.proxy, headers=self.headers)
  File "/home/airflow/.local/lib/python3.10/site-packages/requests/api.py", line 73, in get
    return request("get", url, params=params, **kwargs)
  File "/home/airflow/.local/lib/python3.10/site-packages/requests/api.py", line 59, in request
    return session.request(method=method, url=url, **kwargs)
  File "/home/airflow/.local/lib/python3.10/site-packages/requests/sessions.py", line 589, in request
    resp = self.send(prep, **send_kwargs)
  File "/home/airflow/.local/lib/python3.10/site-packages/requests/sessions.py", line 703, in send
    r = adapter.send(request, **kwargs)
  File "/home/airflow/.local/lib/python3.10/site-packages/requests/adapters.py", line 519, in send
    raise ConnectionError(e, request=request)
requests.exceptions.ConnectionError: HTTPSConnectionPool(host='www.alphavantage.co', port=443): Max retries exceeded with url: /query?function=TIME_SERIES_DAILY&symbol=AAPL&outputsize=full&apikey=D4FOXZ3SY45T4YFI&datatype=json (Caused by NewConnectionError('<urllib3.connection.HTTPSConnection object at 0x7fd0a6624130>: Failed to establish a new connection: [Errno -3] Temporary failure in name resolution'))
[2025-05-12T08:58:06.336+0000] {taskinstance.py:1400} INFO - Marking task as FAILED. dag_id=stock_etl_alpha_vantage_minio_only, task_id=extract_stock_data, execution_date=20250511T000000, start_date=20250512T085741, end_date=20250512T085806
[2025-05-12T08:58:06.891+0000] {standard_task_runner.py:104} ERROR - Failed to execute job 4 for task extract_stock_data (HTTPSConnectionPool(host='www.alphavantage.co', port=443): Max retries exceeded with url: /query?function=TIME_SERIES_DAILY&symbol=AAPL&outputsize=full&apikey=D4FOXZ3SY45T4YFI&datatype=json (Caused by NewConnectionError('<urllib3.connection.HTTPSConnection object at 0x7fd0a6624130>: Failed to establish a new connection: [Errno -3] Temporary failure in name resolution')); 261)
[2025-05-12T08:58:07.050+0000] {local_task_job_runner.py:228} INFO - Task exited with return code 1
[2025-05-12T08:58:07.959+0000] {taskinstance.py:2778} INFO - 0 downstream tasks scheduled from follow-on schedule check
